<mujoco model="real">

    <compiler angle="degree" coordinate="local" inertiafromgeom="true" />
    <option integrator="RK4" timestep="0.02" />


    <default>
        <joint armature="1" damping="1" limited="true" />
        <geom conaffinity="0" condim="1" density="0.01" friction="0.5 0.5 0.1" margin="0.01" rgba="1 1 0 1" />
    </default>


    <asset>

        <texture builtin="gradient" height="100" rgb1="0.4 0.7 1" rgb2="0 0 0" type="skybox" width="100" />


        <texture builtin="flat" height="1278" mark="cross" markrgb="1 0 1" name="texgeom" random="0.01" rgb1="0.8 0.6 0.9" rgb2="0.8 0.6 0.4" type="cube" width="127" />
        <texture builtin="checker" height="100" name="texplane" rgb1="0 0 0" rgb2="0.8 0.8 0.8" type="2d" width="100" />
        <material name="MatPlane" reflectance="0.1" shininess="1" specular="1" texrepeat="60 60" texture="texplane" />
        <material name="geom" texture="texgeom" texuniform="true" />

        <mesh file="stl/cattorso.stl" name="torso" scale="0.01 0.01 0.01" />
        <mesh file="stl/hip.stl" name="hip" scale="0.01 0.01 0.01" />
        <mesh file="stl/kneeFR.stl" name="kneeFR" scale="0.01 0.01 0.01" />
        <mesh file="stl/kneeFL.stl" name="kneeFL" scale="0.01 0.01 0.01" />
        <mesh file="stl/kneeBR.stl" name="kneeBR" scale="0.01 0.01 0.01" />
        <mesh file="stl/kneeBL.stl" name="kneeBL" scale="0.01 0.01 0.01" />
        <mesh file="stl/foot.stl" name="foot" scale="0.01 0.01 0.01" />
    </asset>   
    
    


    <worldbody>

        <light cutoff="100" diffuse="1 1 1" dir="-0 0 -1.3" directional="true" exponent="1" pos="0 0 1.3" specular=".1 .1 .1" />
        <geom conaffinity="1" condim="3" material="MatPlane" name="floor" pos="0 0 0" rgba="0.2 0.3 0.3 1" size="10 10 10" type="plane" />

         <geom name="target" pos="5 0.4 2 " rgba="1 0 0 1" size="0.1" type="sphere" />




        <camera euler="0 0 0" mode="fixed" name="birds_eye" pos="0 0 25" />
        <camera euler="30 -35 -40" mode="fixed" name="isometric_view" pos="-10 -10 13" />
        <body euler="0 0 0" name="torso" pos="0 0 0.7639233145583532">
            <site name="torso_sensor_zone" pos="0 0 0.5" rgba="1 1 1 1" size=".1 .1 .1" type="ellipsoid" /> 
            <camera euler="90 -90 0" mode="fixed" name="eye" pos="0.5 0 1" />
            <joint armature="0" damping="0" limited="false" margin="0.01" name="root" pos="0 0 0" type="free" />
            <geom mesh="torso" pos="0 0 0" rgba="0 1 0 0.97" type="mesh" />



            <body name="hipFR" pos="0.72 0.4 0.15">
                    <joint axis="1 0 0" name="dynamixel_1" pos="0 0 0" range="0 30" type="hinge" />
                    <geom mesh="hip" pos="0 0 0" rgba="1 0 0 0.9" type="mesh" />

                    <body name="kneeFR" pos="0.45 0 0">--&gt;
                        <joint axis="0 1 0" name="dynamixel_2" pos="0 0 0" range="-65 0" type="hinge" />
                        <geom mesh="kneeFR" pos="0 0 0" rgba="0 0 1 0.9" type="mesh" />
                        <body name="footFR" pos="0 0 -0.92">--&gt;
	                        <joint axis="0 1 0" name="dynamixel_3" pos="0 0 0" range="-90 0" type="hinge" />
	                        <geom fromto="0 0 0 0 0 -0.2" pos="0 0 0" rgba="0 1 0 0.9" size="0.1" type="capsule" />
                    	</body>
                    </body>
            </body>

    
            <body name="hipFL" pos="0.72 -0.4 0.15">
                    <joint axis="1 0 0" name="dynamixel_4" pos="0 0 0" range="-30 0" type="hinge" />
                    <geom mesh="hip" pos="0 0 0" rgba="1 0 0 0.9" type="mesh" />

                    <body name="kneeFL" pos="0.45 0 0">--&gt;
                        <joint axis="0 1 0" name="dynamixel_5" pos="0 0 0" range="-65 0" type="hinge" />
                        <geom mesh="kneeFL" pos="0 0 0" rgba="0 0 1 0.9" type="mesh" />
                        <body name="footFL" pos="0 0 -0.92">--&gt;
	                        <joint axis="0 1 0" name="dynamixel_6" pos="0 0 0" range="-90 0" type="hinge" />
	                        <geom fromto="0 0 0 0 0 -0.2" pos="0 0 0" rgba="0 1 0 0.9" size="0.1" type="capsule" />
                    	</body>
                    </body>
            </body>

    
            <body euler="0 0 -180" name="hipBR" pos="-0.8 0.4 0.15">
                    <joint axis="1 0 0" name="dynamixel_7" pos="0 0 0" range="-30 0" type="hinge" />
                    <geom mesh="hip" pos="0 0 0" rgba="1 0 0 0.9" type="mesh" />

                    <body name="kneeBR" pos="0.45 0 0">--&gt;
                        <joint axis="0 1 0" name="dynamixel_8" pos="0 0 0" range="-65 0" type="hinge" />
                        <geom mesh="kneeBR" pos="0 0 0" rgba="0 0 1 0.9" type="mesh" />
                        <body name="footBR" pos="0 0 -0.92">--&gt;
	                        <joint axis="0 1 0" name="dynamixel_9" pos="0 0 0" range="0 90" type="hinge" />
	                        <geom fromto="0 0 0 0 0 -0.2" pos="0 0 0" rgba="0 1 0 0.9" size="0.1" type="capsule" />
                    	</body>
                    </body>
            </body>

    
            <body euler="0 0 -180" name="hipBL" pos="-0.8 -0.4 0.15">&gt;
                    <joint axis="1 0 0" name="dynamixel_10" pos="0 0 0" range="0 30" type="hinge" />
                    <geom mesh="hip" pos="0 0 0" rgba="1 0 0 0.9" type="mesh" />

                    <body name="kneeBL" pos="0.45 0 0">--&gt;
                        <joint axis="0 1 0" name="dynamixel_11" pos="0 0 0" range="-65 0" type="hinge" />
                        <geom mesh="kneeBL" pos="0 0 0" rgba="0 0 1 0.9" type="mesh" />
                        <body name="footBL" pos="0 0 -0.92">--&gt;
	                        <joint axis="0 1 0" name="dynamixel_12" pos="0 0 0" range="0 90" type="hinge" />
	                        <geom fromto="0 0 0 0 0 -0.2" pos="0 0 0" rgba="0 1 0 0.9" size="0.1" type="capsule" />
                    	</body>
                    </body>
            </body>

        </body>
    </worldbody>

    <sensor>
        <framequat name="stability_sensor" objname="torso_sensor_zone" objtype="site" />
    </sensor> --&gt;

    <actuator>
        <velocity ctrllimited="true" ctrlrange="-1 1" forcelimited="true" forcerange="-1 1" gear="1" joint="dynamixel_1" />
        <velocity ctrllimited="true" ctrlrange="-1 1" forcelimited="true" forcerange="-1 1" gear="1" joint="dynamixel_2" />
        <velocity ctrllimited="true" ctrlrange="-1 1" forcelimited="true" forcerange="-1 1" gear="1" joint="dynamixel_3" />
        <velocity ctrllimited="true" ctrlrange="-1 1" forcelimited="true" forcerange="-1 1" gear="1" joint="dynamixel_4" />
        <velocity ctrllimited="true" ctrlrange="-1 1" forcelimited="true" forcerange="-1 1" gear="1" joint="dynamixel_5" />
        <velocity ctrllimited="true" ctrlrange="-1 1" forcelimited="true" forcerange="-1 1" gear="1" joint="dynamixel_6" />
        <velocity ctrllimited="true" ctrlrange="-1 1" forcelimited="true" forcerange="-1 1" gear="1" joint="dynamixel_7" />
        <velocity ctrllimited="true" ctrlrange="-1 1" forcelimited="true" forcerange="-1 1" gear="1" joint="dynamixel_8" />
        <velocity ctrllimited="true" ctrlrange="-1 1" forcelimited="true" forcerange="-1 1" gear="1" joint="dynamixel_9" />
        <velocity ctrllimited="true" ctrlrange="-1 1" forcelimited="true" forcerange="-1 1" gear="1" joint="dynamixel_10" />
        <velocity ctrllimited="true" ctrlrange="-1 1" forcelimited="true" forcerange="-1 1" gear="1" joint="dynamixel_11" />
        <velocity ctrllimited="true" ctrlrange="-1 1" forcelimited="true" forcerange="-1 1" gear="1" joint="dynamixel_12" />
    </actuator>

</mujoco>